{"name": "test_login[test_data1]", "status": "broken", "statusDetails": {"message": "ValueError: There is no such driver by url https://chromedriver.storage.googleapis.com/LATEST_RELEASE_131.0.6778", "trace": "request = <SubRequest 'driver' for <Function test_login[test_data1]>>\n\n    @pytest.fixture\n    def driver(request):\n        config = ConfigReader()\n        browser = config.get_browser_type()\n>       driver = DriverFactory.create_driver(browser)\n\nconftest.py:16: \n_ _ _ _ _ _ _ _ _ _ _ _ _ _ _ _ _ _ _ _ _ _ _ _ _ _ _ _ _ _ _ _ _ _ _ _ _ _ _ _ _ _ _ _ _ _ _ _ _ _ _ _ _ _ _ _ _ _ _ _ _ _ _\nutilities\\driver_factory.py:17: in create_driver\n    ChromeDriverManager().install(),\nC:\\Users\\huyuh\\AppData\\Local\\Programs\\Python\\Python313\\Lib\\site-packages\\webdriver_manager\\chrome.py:32: in install\n    driver_path = self._get_driver_path(self.driver)\nC:\\Users\\huyuh\\AppData\\Local\\Programs\\Python\\Python313\\Lib\\site-packages\\webdriver_manager\\manager.py:23: in _get_driver_path\n    driver_version = driver.get_version()\nC:\\Users\\huyuh\\AppData\\Local\\Programs\\Python\\Python313\\Lib\\site-packages\\webdriver_manager\\driver.py:41: in get_version\n    return self.get_latest_release_version()\nC:\\Users\\huyuh\\AppData\\Local\\Programs\\Python\\Python313\\Lib\\site-packages\\webdriver_manager\\driver.py:74: in get_latest_release_version\n    validate_response(resp)\n_ _ _ _ _ _ _ _ _ _ _ _ _ _ _ _ _ _ _ _ _ _ _ _ _ _ _ _ _ _ _ _ _ _ _ _ _ _ _ _ _ _ _ _ _ _ _ _ _ _ _ _ _ _ _ _ _ _ _ _ _ _ _\n\nresp = <Response [404]>\n\n    def validate_response(resp):\n        if resp.status_code == 404:\n>           raise ValueError(\"There is no such driver by url {}\".format(resp.url))\nE           ValueError: There is no such driver by url https://chromedriver.storage.googleapis.com/LATEST_RELEASE_131.0.6778\n\nC:\\Users\\huyuh\\AppData\\Local\\Programs\\Python\\Python313\\Lib\\site-packages\\webdriver_manager\\utils.py:80: ValueError"}, "attachments": [{"name": "log", "source": "65ca8d63-c97c-4d3a-9b89-74e459c3b575-attachment.txt", "type": "text/plain"}, {"name": "stderr", "source": "3785b021-be28-4080-84e6-ecbf60b447e1-attachment.txt", "type": "text/plain"}], "parameters": [{"name": "test_data", "value": "{'username': 'invalid@email.com', 'password': 'wrong123', 'expected_result': 'failure', 'error_message': 'Warning: No match for E-Mail Address and/or Password.'}"}], "start": 1735548354565, "stop": 1735548354565, "uuid": "514d304f-2908-469c-b947-480acc26c5e9", "historyId": "f0ac8dbe414c3638c5b4ee3b44ae5bb0", "testCaseId": "2116f0ad00ab1de0effc54f114dd9496", "fullName": "tests.test_login.TestLogin#test_login", "labels": [{"name": "severity", "value": "critical"}, {"name": "feature", "value": "로그인"}, {"name": "story", "value": "데이터 기반 로그인 테스트"}, {"name": "parentSuite", "value": "tests"}, {"name": "suite", "value": "test_login"}, {"name": "subSuite", "value": "TestLogin"}, {"name": "host", "value": "JiHee"}, {"name": "thread", "value": "35048-MainThread"}, {"name": "framework", "value": "pytest"}, {"name": "language", "value": "cpython3"}, {"name": "package", "value": "tests.test_login"}]}